<?xml version="1.0"?>
<!-- =================================================================================== -->
<!-- |    This document was autogenerated by xacro from rb10_1300e.urdf.xacro          | -->
<!-- |    EDITING THIS FILE BY HAND IS NOT RECOMMENDED                                 | -->
<!-- =================================================================================== -->
<robot name="dda_rb10_1300e">
  <link name="dda_link0">
    <visual>
      <geometry>
        <mesh filename="./meshes/rb10_1300e/visual/link0.dae" />
      </geometry>
    </visual>
    <collision>
      <geometry>
        <mesh filename="./meshes/rb10_1300e/collision/link0.stl" />
      </geometry>
    </collision>
  </link>
  <link name="dda_link1">
    <visual>
      <geometry>
        <mesh filename="./meshes/rb10_1300e/visual/link1.dae" />
      </geometry>
    </visual>
    <collision>
      <geometry>
        <mesh filename="./meshes/rb10_1300e/collision/link1.stl" />
      </geometry>
    </collision>
    <inertial>
      <origin rpy="0 0 0" xyz="0.000021 -0.007855 -0.042537" />
      <mass value="8.366" />
      <inertia ixx="0.027403652" ixy="-5.926e-06" ixz="-1.0119e-05" iyy="0.027770573"
        iyz="0.003030512" izz="0.026140211" />
    </inertial>
  </link>
  <link name="dda_link2">
    <visual>
      <geometry>
        <mesh filename="./meshes/rb10_1300e/visual/link2.dae" />
      </geometry>
    </visual>
    <collision>
      <geometry>
        <mesh filename="./meshes/rb10_1300e/collision/link2.stl" />
      </geometry>
    </collision>
    <inertial>
      <origin rpy="0 0 0" xyz="-0.000013 -0.155462 0.225241" />
      <mass value="15.61" />
      <inertia ixx="1.140650644" ixy="-1.3042e-05" ixz="-6.7084e-05" iyy="1.134398623"
        iyz="0.024507884" izz="0.050849068" />
    </inertial>
  </link>
  <link name="dda_link3">
    <visual>
      <geometry>
        <mesh filename="./meshes/rb10_1300e/visual/link3.dae" />
      </geometry>
    </visual>
    <collision>
      <geometry>
        <mesh filename="./meshes/rb10_1300e/collision/link3.stl" />
      </geometry>
    </collision>
    <inertial>
      <origin rpy="0 0 0" xyz="-0.000048 -0.013885 0.325013" />
      <mass value="5.69" />
      <inertia ixx="0.312033029" ixy="9.298e-06" ixz="1.169e-05" iyy="0.311287646" iyz="0.005331552"
        izz="0.011397824" />
    </inertial>
  </link>
  <link name="dda_link4">
    <visual>
      <geometry>
        <mesh filename="./meshes/rb10_1300e/visual/link4.dae" />
      </geometry>
    </visual>
    <collision>
      <geometry>
        <mesh filename="./meshes/rb10_1300e/collision/link4.stl" />
      </geometry>
    </collision>
    <inertial>
      <origin rpy="0 0 0" xyz="0.000093 -0.113949 0.026461" />
      <mass value="2.062" />
      <inertia ixx="0.0027111" ixy="-8.022e-06" ixz="1.1208e-05" iyy="0.002715407" iyz="0.000144243"
        izz="0.002157043" />
    </inertial>
  </link>
  <link name="dda_link5">
    <visual>
      <geometry>
        <mesh filename="./meshes/rb10_1300e/visual/link5.dae" />
      </geometry>
    </visual>
    <collision>
      <geometry>
        <mesh filename="./meshes/rb10_1300e/collision/link5.stl" />
      </geometry>
    </collision>
    <inertial>
      <origin rpy="0 0 0" xyz="-0.000093 -0.026434 -0.003233" />
      <mass value="2.061" />
      <inertia ixx="0.002706437" ixy="1.1205e-05" ixz="-8.016e-06" iyy="0.002153592"
        iyz="0.000141528" izz="0.002712272" />
    </inertial>
  </link>
  <link name="dda_link6">
    <visual>
      <geometry>
        <mesh filename="./meshes/rb10_1300e/visual/link6.dae" />
      </geometry>
    </visual>
    <collision>
      <geometry>
        <mesh filename="./meshes/rb10_1300e/collision/link6.stl" />
      </geometry>
    </collision>
    <inertial>
      <origin rpy="0 0 0" xyz="-0.000210 -0.092540 -0.000292" />
      <mass value="0.406" />
      <inertia ixx="0.000345314" ixy="5.73e-07" ixz="6.61e-07" iyy="0.000532873" iyz="-5.4e-08"
        izz="0.000340021" />
    </inertial>
  </link>
  <link name="dda_link_end">
    <inertial>
      <origin xyz="2.94628820194806e-07 -0.014999799194710131 6.035655293378008e-17" rpy="0 0 0" />
      <mass value="10.402034999999998" />
      <inertia ixx="0.015852" iyy="0.112139" izz="0.097847" ixy="-0.0" iyz="0.0" ixz="0.0" />
    </inertial>
    <visual>
      <origin xyz="-0.0 0.1163 -0.0" rpy="0 0 0" />
      <geometry>
        <mesh filename="./meshes/link_dda.stl" scale="0.001 0.001 0.001" />
      </geometry>
      <material name="silver" />
    </visual>
    <collision>
      <origin xyz="-0.0 0.1163 -0.0" rpy="0 0 0" />
      <geometry>
        <mesh filename="./meshes/link_dda.stl" scale="0.001 0.001 0.001" />
      </geometry>
    </collision>
  </link>
  <link name="dda_link_tcp" />
  <joint name="dda_joint_base" type="revolute">
    <origin rpy="0 0 0" xyz="0 0 0" />
    <parent link="dda_link0" />
    <child link="dda_link1" />
    <axis xyz="0 0 1" />
    <limit effort="10" lower="-3.14" upper="3.14" velocity="3.14" />
  </joint>
  <joint name="dda_joint_shoulder" type="revolute">
    <origin rpy="0 0 0" xyz="0 0 0.197" />
    <parent link="dda_link1" />
    <child link="dda_link2" />
    <axis xyz="0 1 0" />
    <limit effort="10" lower="-3.14" upper="3.14" velocity="3.14" />
  </joint>
  <joint name="dda_joint_elbow" type="revolute">
    <origin rpy="0 0 0" xyz="0 -0.1875 0.6127" />
    <parent link="dda_link2" />
    <child link="dda_link3" />
    <axis xyz="0 1 0" />
    <limit effort="10" lower="-3.14" upper="3.14" velocity="3.14" />
  </joint>
  <joint name="dda_joint_wrist1" type="revolute">
    <origin rpy="0 0 0" xyz="0 0.1484 0.57015" />
    <parent link="dda_link3" />
    <child link="dda_link4" />
    <axis xyz="0 1 0" />
    <limit effort="10" lower="-3.14" upper="3.14" velocity="3.14" />
  </joint>
  <joint name="dda_joint_wrist2" type="revolute">
    <origin rpy="0 0 0" xyz="0 -0.11715 0" />
    <parent link="dda_link4" />
    <child link="dda_link5" />
    <axis xyz="0 0 1" />
    <limit effort="10" lower="-3.14" upper="3.14" velocity="3.14" />
  </joint>
  <joint name="dda_joint_wrist3" type="revolute">
    <origin rpy="0 0 0" xyz="0 0 0.11715" />
    <parent link="dda_link5" />
    <child link="dda_link6" />
    <axis xyz="0 1 0" />
    <limit effort="10" lower="-3.14" upper="3.14" velocity="3.14" />
  </joint>
  <joint name="dda_joint_end" type="fixed">
    <origin xyz="0.0 -0.1163 0.0" rpy="0 0 0" />
    <parent link="dda_link6" />
    <child link="dda_link_end" />
  </joint>
  <joint name="dda_joint_tcp" type="fixed">
    <origin xyz="0.0 -0.03 0.0" rpy="0 0 -1.57" />
    <parent link="dda_link_end" />
    <child link="dda_link_tcp" />
  </joint>
</robot>