<?xml version="1.0"?>
<robot name="simple_robot">
  <link name="base_link">
    <visual>
      <geometry>
        <box size="0.5 0.5 0.1"/>
      </geometry>
      <material name="blue">
        <color rgba="0 0 0.8 1"/>
      </material>
    </visual>
  </link>
  
  <link name="arm_link">
    <visual>
      <geometry>
        <box size="0.1 0.1 0.5"/>
      </geometry>
      <material name="red">
        <color rgba="0.8 0 0 1"/>
      </material>
    </visual>
  </link>
  
  <joint name="base_to_arm" type="revolute">
    <parent link="base_link"/>
    <child link="arm_link"/>
    <axis xyz="0 1 0"/>
    <origin xyz="0 0 0.3"/>
    <limit lower="-1.57" upper="1.57" effort="10" velocity="3"/>
  </joint>
</robot> 